Workbook
Name IQ_CH: 110000
Name IQ_CQ: 5000
Name IQ_CY: 10000
Name IQ_DAILY: 500000
Name IQ_FH: 100000
Name IQ_FQ: 500
Name IQ_FY: 1000
Name IQ_LTM: 2000
Name IQ_MONTH: 15000
Name IQ_NTM: 6000
Name IQ_WEEK: 50000
Name IQ_YTD: 3000
Name UPDATE: 'Data Sheet'!$E$1

Sheet Financials>

Sheet HistoricalFS
B2: ="Historical Financial Statement - "&'Data Sheet'!B1 -> Historical Financial Statement - TITAN COMPANY LTD
B3: Years | C3: ='Data Sheet'!B16 -> 42825 | D3: ='Data Sheet'!C16 -> 43190 | E3: ='Data Sheet'!D16 -> 43555 | F3: ='Data Sheet'!E16 -> 43921 | G3: ='Data Sheet'!F16 -> 44286 | H3: ='Data Sheet'!G16 -> 44651 | I3: ='Data Sheet'!H16 -> 45016 | J3: ='Data Sheet'!I16 -> 45382 | ... L3: ='Data Sheet'!K16 -> 46112
A5: # | B5: Income Statement
B6: Sales | C6: =IFERROR('Data Sheet'!B17,0) -> 13260.83 | D6: =IFERROR('Data Sheet'!C17,0) -> 16119.77 | E6: =IFERROR('Data Sheet'!D17,0) -> 19778.52 | F6: =IFERROR('Data Sheet'!E17,0) -> 21052 | G6: =IFERROR('Data Sheet'!F17,0) -> 21644 | H6: =IFERROR('Data Sheet'!G17,0) -> 28799 | I6: =IFERROR('Data Sheet'!H17,0) -> 40575 | J6: =IFERROR('Data Sheet'!I17,0) -> 51084 | ... L6: =IFERROR('Data Sheet'!K17,0) -> 87584
B7: Sales Growth | C7: - | D7: =D6/C6-1 -> 0.21559284 | E7: =E6/D6-1 -> 0.22697284 | F7: =F6/E6-1 -> 0.064387022 | G7: =G6/F6-1 -> 0.028120844 | H7: =H6/G6-1 -> 0.3305766 | I7: =I6/H6-1 -> 0.40890309 | J7: =J6/I6-1 -> 0.25900185 | K7: =K6/J6-1 -> 0.18346253 | L7: =L6/K6-1 -> 0.44872304
B9: COGS | C9: =IFERROR(SUM('Data Sheet'!B18,'Data Sheet'!B20:B22)-'Data Sheet'!B19,0) -> 10606.01 | D9: =IFERROR(SUM('Data Sheet'!C18,'Data Sheet'!C20:C22)-'Data Sheet'!C19,0) -> 12762.63 | E9: =IFERROR(SUM('Data Sheet'!D18,'Data Sheet'!D20:D22)-'Data Sheet'!D19,0) -> 15660.48 | F9: =IFERROR(SUM('Data Sheet'!E18,'Data Sheet'!E20:E22)-'Data Sheet'!E19,0) -> 16626 | G9: =IFERROR(SUM('Data Sheet'!F18,'Data Sheet'!F20:F22)-'Data Sheet'!F19,0) -> 17661 | H9: =IFERROR(SUM('Data Sheet'!G18,'Data Sheet'!G20:G22)-'Data Sheet'!G19,0) -> 23225 | I9: =IFERROR(SUM('Data Sheet'!H18,'Data Sheet'!H20:H22)-'Data Sheet'!H19,0) -> 32295 | J9: =IFERROR(SUM('Data Sheet'!I18,'Data Sheet'!I20:I22)-'Data Sheet'!I19,0) -> 41664 | ... L9: =IFERROR(SUM('Data Sheet'!K18,'Data Sheet'!K20:K22)-'Data Sheet'!K19,0) -> 73461
B10: COGS % Sales | C10: =C9/C6 -> 0.79979986 | D10: =D9/D6 -> 0.79173772 | E10: =E9/E6 -> 0.79179231 | F10: =F9/F6 -> 0.78975869 | G10: =G9/G6 -> 0.81597671 | H10: =H9/H6 -> 0.80645161 | I10: =I9/I6 -> 0.79593346 | J10: =J9/J6 -> 0.81559784 | ... L10: =L9/L6 -> 0.83874909
B12: Gross Profit | C12: =C6-C9 -> 2654.82 | D12: =D6-D9 -> 3357.14 | E12: =E6-E9 -> 4118.04 | F12: =F6-F9 -> 4426 | G12: =G6-G9 -> 3983 | H12: =H6-H9 -> 5574 | I12: =I6-I9 -> 8280 | J12: =J6-J9 -> 9420 | ... L12: =L6-L9 -> 14123
B13: Gross Margins | C13: =C12/C6 -> 0.20020014 | D13: =D12/D6 -> 0.20826228 | E13: =E12/E6 -> 0.20820769 | F13: =F12/F6 -> 0.21024131 | G13: =G12/G6 -> 0.18402329 | H13: =H12/H6 -> 0.19354839 | I13: =I12/I6 -> 0.20406654 | J13: =J12/J6 -> 0.18440216 | ... L13: =L12/L6 -> 0.16125091
B15: Selling & General Expenses | C15: =IFERROR(SUM('Data Sheet'!B23:B24),0) -> 1490.92 | D15: =IFERROR(SUM('Data Sheet'!C23:C24),0) -> 1712.94 | E15: =IFERROR(SUM('Data Sheet'!D23:D24),0) -> 2124.25 | F15: =IFERROR(SUM('Data Sheet'!E23:E24),0) -> 1963 | G15: =IFERROR(SUM('Data Sheet'!F23:F24),0) -> 2258 | H15: =IFERROR(SUM('Data Sheet'!G23:G24),0) -> 2230 | I15: =IFERROR(SUM('Data Sheet'!H23:H24),0) -> 3398 | J15: =IFERROR(SUM('Data Sheet'!I23:I24),0) -> 4128 | ... L15: =IFERROR(SUM('Data Sheet'!K23:K24),0) -> 5766
B16: S&G Exp % Sales | C16: =C15/C6 -> 0.11243037 | D16: =D15/D6 -> 0.1062633 | E16: =E15/E6 -> 0.10740187 | F16: =F15/F6 -> 0.093245297 | G16: =G15/G6 -> 0.10432452 | H16: =H15/H6 -> 0.077433244 | I16: =I15/I6 -> 0.083746149 | J16: =J15/J6 -> 0.080808081 | ... L16: =L15/L6 -> 0.065833942
B18: EBITDA | C18: =C12-C15 -> 1163.9 | D18: =D12-D15 -> 1644.2 | E18: =E12-E15 -> 1993.79 | F18: =F12-F15 -> 2463 | G18: =G12-G15 -> 1725 | H18: =H12-H15 -> 3344 | I18: =I12-I15 -> 4882 | J18: =J12-J15 -> 5292 | ... L18: =L12-L15 -> 8357
B19: EBITDA Margins | C19: =C18/C6 -> 0.08776977 | D19: =D18/D6 -> 0.10199897 | E19: =E18/E6 -> 0.10080582 | F19: =F18/F6 -> 0.11699601 | G19: =G18/G6 -> 0.079698762 | H19: =H18/H6 -> 0.11611514 | I19: =I18/I6 -> 0.12032039 | J19: =J18/J6 -> 0.10359408 | ... L19: =L18/L6 -> 0.095416971
B21: Interest | C21: =IFERROR('Data Sheet'!B27,0) -> 37.74 | D21: =IFERROR('Data Sheet'!C27,0) -> 52.92 | E21: =IFERROR('Data Sheet'!D27,0) -> 52.54 | F21: =IFERROR('Data Sheet'!E27,0) -> 166 | G21: =IFERROR('Data Sheet'!F27,0) -> 203 | H21: =IFERROR('Data Sheet'!G27,0) -> 218 | I21: =IFERROR('Data Sheet'!H27,0) -> 300 | J21: =IFERROR('Data Sheet'!I27,0) -> 619 | ... L21: =IFERROR('Data Sheet'!K27,0) -> 1180
B22: Interest % Sales | C22: =C21/C6 -> 0.0028459757 | D22: =D21/D6 -> 0.0032829253 | E22: =E21/E6 -> 0.0026564172 | F22: =F21/F6 -> 0.0078852366 | G22: =G21/G6 -> 0.0093790427 | H22: =H21/H6 -> 0.0075697073 | I22: =I21/I6 -> 0.0073937153 | J22: =J21/J6 -> 0.012117297 | ... L22: =L21/L6 -> 0.01347278
B24: Depreciation | C24: =IFERROR('Data Sheet'!B26,0) -> 110.53 | D24: =IFERROR('Data Sheet'!C26,0) -> 131.43 | E24: =IFERROR('Data Sheet'!D26,0) -> 162.84 | F24: =IFERROR('Data Sheet'!E26,0) -> 348 | G24: =IFERROR('Data Sheet'!F26,0) -> 375 | H24: =IFERROR('Data Sheet'!G26,0) -> 399 | I24: =IFERROR('Data Sheet'!H26,0) -> 441 | J24: =IFERROR('Data Sheet'!I26,0) -> 584 | ... L24: =IFERROR('Data Sheet'!K26,0) -> 826
B25: Depreciation%Sales | C25: =C24/C6 -> 0.008335074 | D25: =D24/D6 -> 0.0081533421 | E25: =E24/E6 -> 0.0082331742 | F25: =F24/F6 -> 0.016530496 | G25: =G24/G6 -> 0.017325818 | H25: =H24/H6 -> 0.013854648 | I25: =I24/I6 -> 0.010868762 | J25: =J24/J6 -> 0.011432151 | ... L25: =L24/L6 -> 0.0094309463
B27: Earnings Before Tax | C27: =IFERROR(C18-SUM(C24,C21),0) -> 1015.63 | D27: =IFERROR(D18-SUM(D24,D21),0) -> 1459.85 | E27: =IFERROR(E18-SUM(E24,E21),0) -> 1778.41 | F27: =IFERROR(F18-SUM(F24,F21),0) -> 1949 | G27: =IFERROR(G18-SUM(G24,G21),0) -> 1147 | H27: =IFERROR(H18-SUM(H24,H21),0) -> 2727 | I27: =IFERROR(I18-SUM(I24,I21),0) -> 4141 | J27: =IFERROR(J18-SUM(J24,J21),0) -> 4089 | ... L27: =IFERROR(L18-SUM(L24,L21),0) -> 6351
B28: EBT % Sales | C28: =C27/C6 -> 0.07658872 | D28: =D27/D6 -> 0.090562707 | E28: =E27/E6 -> 0.089916232 | F28: =F27/F6 -> 0.092580277 | G28: =G27/G6 -> 0.052993901 | H28: =H27/H6 -> 0.094690788 | I28: =I27/I6 -> 0.10205792 | J28: =J27/J6 -> 0.080044632 | ... L28: =L27/L6 -> 0.072513244
B30: Tax | C30: =IFERROR('Data Sheet'!B29,0) -> 275.97 | D30: =IFERROR('Data Sheet'!C29,0) -> 427.87 | E30: =IFERROR('Data Sheet'!D29,0) -> 568.24 | F30: =IFERROR('Data Sheet'!E29,0) -> 609 | G30: =IFERROR('Data Sheet'!F29,0) -> 353 | H30: =IFERROR('Data Sheet'!G29,0) -> 706 | I30: =IFERROR('Data Sheet'!H29,0) -> 1173 | J30: =IFERROR('Data Sheet'!I29,0) -> 1127 | ... L30: =IFERROR('Data Sheet'!K29,0) -> 1728
B31: Effective Tax Rate | C31: =C30/C27 -> 0.27172297 | D31: =D30/D27 -> 0.29309176 | E31: =E30/E27 -> 0.31952137 | F31: =F30/F27 -> 0.31246793 | G31: =G30/G27 -> 0.30775937 | H31: =H30/H27 -> 0.25889256 | I31: =I30/I27 -> 0.28326491 | J31: =J30/J27 -> 0.27561751 | ... L31: =L30/L27 -> 0.27208314
B33: Net Profit | C33: =IFERROR(C27-C30,0) -> 739.66 | D33: =IFERROR(D27-D30,0) -> 1031.98 | E33: =IFERROR(E27-E30,0) -> 1210.17 | F33: =IFERROR(F27-F30,0) -> 1340 | G33: =IFERROR(G27-G30,0) -> 794 | H33: =IFERROR(H27-H30,0) -> 2021 | I33: =IFERROR(I27-I30,0) -> 2968 | J33: =IFERROR(J27-J30,0) -> 2962 | ... L33: =IFERROR(L27-L30,0) -> 4623
B34: Net Margins | C34: =C33/C6 -> 0.055777806 | D34: =D33/D6 -> 0.064019524 | E34: =E33/E6 -> 0.061186075 | F34: =F33/F6 -> 0.06365191 | G34: =G33/G6 -> 0.036684532 | H34: =H33/H6 -> 0.070176048 | I34: =I33/I6 -> 0.07314849 | J34: =J33/J6 -> 0.05798293 | ... L34: =L33/L6 -> 0.052783613
B36: No of Equity Shares | C36: =IFERROR('Data Sheet'!B93,0) -> 88.78 | D36: =IFERROR('Data Sheet'!C93,0) -> 88.78 | E36: =IFERROR('Data Sheet'!D93,0) -> 88.78 | F36: =IFERROR('Data Sheet'!E93,0) -> 88.78 | G36: =IFERROR('Data Sheet'!F93,0) -> 88.78 | H36: =IFERROR('Data Sheet'!G93,0) -> 88.78 | I36: =IFERROR('Data Sheet'!H93,0) -> 88.78 | J36: =IFERROR('Data Sheet'!I93,0) -> 88.78 | ... L36: =IFERROR('Data Sheet'!K93,0) -> 88.78
B38: Earnings per Share | C38: =IFERROR(C33/C36,0) -> 8.3313809 | D38: =IFERROR(D33/D36,0) -> 11.624014 | E38: =IFERROR(E33/E36,0) -> 13.631111 | F38: =IFERROR(F33/F36,0) -> 15.09349 | G38: =IFERROR(G33/G36,0) -> 8.9434557 | H38: =IFERROR(H33/H36,0) -> 22.764136 | I38: =IFERROR(I33/I36,0) -> 33.430953 | J38: =IFERROR(J33/J36,0) -> 33.36337 | ... L38: =IFERROR(L33/L36,0) -> 52.072539
B39: EPS Growth % | D39: =IFERROR(D38/C38-1,0) -> 0.39520861 | E39: =IFERROR(E38/D38-1,0) -> 0.17266807 | F39: =IFERROR(F38/E38-1,0) -> 0.10728245 | G39: =IFERROR(G38/F38-1,0) -> -0.40746269 | H39: =IFERROR(H38/G38-1,0) -> 1.5453401 | I39: =IFERROR(I38/H38-1,0) -> 0.46857991 | J39: =IFERROR(J38/I38-1,0) -> -0.0020215633 | K39: =IFERROR(K38/J38-1,0) -> -0.037812289 | L39: =IFERROR(L38/K38-1,0) -> 0.62210526
B41: Dividend per Share | C41: =IFERROR('Data Sheet'!B31/HistoricalFS!C36,0) -> 2.6000225 | D41: =IFERROR('Data Sheet'!C31/HistoricalFS!D36,0) -> 3.7499437 | E41: =IFERROR('Data Sheet'!D31/HistoricalFS!E36,0) -> 5 | F41: =IFERROR('Data Sheet'!E31/HistoricalFS!F36,0) -> 4.0099121 | G41: =IFERROR('Data Sheet'!F31/HistoricalFS!G36,0) -> 4.0099121 | H41: =IFERROR('Data Sheet'!G31/HistoricalFS!H36,0) -> 7.5185853 | I41: =IFERROR('Data Sheet'!H31/HistoricalFS!I36,0) -> 10.02478 | J41: =IFERROR('Data Sheet'!I31/HistoricalFS!J36,0) -> 11.027258 | ... L41: =IFERROR('Data Sheet'!K31/HistoricalFS!L36,0) -> 15.037171
B42: Dividend payout ratio | C42: =IFERROR(C41/C38,0) -> 0.31207582 | D42: =IFERROR(D41/D38,0) -> 0.32260315 | E42: =IFERROR(E41/E38,0) -> 0.36680797 | F42: =IFERROR(F41/F38,0) -> 0.26567164 | G42: =IFERROR(G41/G38,0) -> 0.44836272 | H42: =IFERROR(H41/H38,0) -> 0.33028204 | I42: =IFERROR(I41/I38,0) -> 0.29986523 | J42: =IFERROR(J41/J38,0) -> 0.33051992 | ... L42: =IFERROR(L41/L38,0) -> 0.28877352
B44: Retained Earnings | C44: =IFERROR(IF(C38>C41,1-C42,0),0) -> 0.68792418 | D44: =IFERROR(IF(D38>D41,1-D42,0),0) -> 0.67739685 | E44: =IFERROR(IF(E38>E41,1-E42,0),0) -> 0.63319203 | F44: =IFERROR(IF(F38>F41,1-F42,0),0) -> 0.73432836 | G44: =IFERROR(IF(G38>G41,1-G42,0),0) -> 0.55163728 | H44: =IFERROR(IF(H38>H41,1-H42,0),0) -> 0.66971796 | I44: =IFERROR(IF(I38>I41,1-I42,0),0) -> 0.70013477 | J44: =IFERROR(IF(J38>J41,1-J42,0),0) -> 0.66948008 | ... L44: =IFERROR(IF(L38>L41,1-L42,0),0) -> 0.71122648
A46: # | B46: Balance Sheet
B47: Equity Share Capital | C47: =IFERROR('Data Sheet'!B57,0) -> 88.78 | D47: =IFERROR('Data Sheet'!C57,0) -> 88.78 | E47: =IFERROR('Data Sheet'!D57,0) -> 88.78 | F47: =IFERROR('Data Sheet'!E57,0) -> 89 | G47: =IFERROR('Data Sheet'!F57,0) -> 89 | H47: =IFERROR('Data Sheet'!G57,0) -> 89 | I47: =IFERROR('Data Sheet'!H57,0) -> 89 | J47: =IFERROR('Data Sheet'!I57,0) -> 89 | ... L47: =IFERROR('Data Sheet'!K57,0) -> 89
B48: Reserves | C48: =IFERROR('Data Sheet'!B58,0) -> 4143.6 | D48: =IFERROR('Data Sheet'!C58,0) -> 5001.1 | E48: =IFERROR('Data Sheet'!D58,0) -> 5981.37 | F48: =IFERROR('Data Sheet'!E58,0) -> 6580 | G48: =IFERROR('Data Sheet'!F58,0) -> 7408 | H48: =IFERROR('Data Sheet'!G58,0) -> 9214 | I48: =IFERROR('Data Sheet'!H58,0) -> 11762 | J48: =IFERROR('Data Sheet'!I58,0) -> 9304 | ... L48: =IFERROR('Data Sheet'!K58,0) -> 15614
B49: Borrowings | C49: =IFERROR('Data Sheet'!B59,0) -> 1882.43 | D49: =IFERROR('Data Sheet'!C59,0) -> 1691.01 | E49: =IFERROR('Data Sheet'!D59,0) -> 2392.98 | F49: =IFERROR('Data Sheet'!E59,0) -> 3562 | G49: =IFERROR('Data Sheet'!F59,0) -> 5638 | H49: =IFERROR('Data Sheet'!G59,0) -> 7275 | I49: =IFERROR('Data Sheet'!H59,0) -> 9367 | J49: =IFERROR('Data Sheet'!I59,0) -> 15528 | ... L49: =IFERROR('Data Sheet'!K59,0) -> 30621
B50: Other Liabilities | C50: =IFERROR('Data Sheet'!B60,0) -> 2292.76 | D50: =IFERROR('Data Sheet'!C60,0) -> 2740.15 | E50: =IFERROR('Data Sheet'!D60,0) -> 3246.71 | F50: =IFERROR('Data Sheet'!E60,0) -> 3313 | G50: =IFERROR('Data Sheet'!F60,0) -> 3309 | H50: =IFERROR('Data Sheet'!G60,0) -> 4610 | I50: =IFERROR('Data Sheet'!H60,0) -> 5802 | J50: =IFERROR('Data Sheet'!I60,0) -> 6626 | ... L50: =IFERROR('Data Sheet'!K60,0) -> 14237
B51: Total Liabilities | C51: =IFERROR('Data Sheet'!B61,0) -> 8407.57 | D51: =IFERROR('Data Sheet'!C61,0) -> 9521.04 | E51: =IFERROR('Data Sheet'!D61,0) -> 11709.84 | F51: =IFERROR('Data Sheet'!E61,0) -> 13544 | G51: =IFERROR('Data Sheet'!F61,0) -> 16444 | H51: =IFERROR('Data Sheet'!G61,0) -> 21188 | I51: =IFERROR('Data Sheet'!H61,0) -> 27020 | J51: =IFERROR('Data Sheet'!I61,0) -> 31547 | ... L51: =IFERROR('Data Sheet'!K61,0) -> 60561
B53: Fixed Assets Net Block | C53: =IFERROR('Data Sheet'!B62,0) -> 1188.72 | D53: =IFERROR('Data Sheet'!C62,0) -> 1473.81 | E53: =IFERROR('Data Sheet'!D62,0) -> 1566.63 | F53: =IFERROR('Data Sheet'!E62,0) -> 2633 | G53: =IFERROR('Data Sheet'!F62,0) -> 2523 | H53: =IFERROR('Data Sheet'!G62,0) -> 2544 | I53: =IFERROR('Data Sheet'!H62,0) -> 2998 | J53: =IFERROR('Data Sheet'!I62,0) -> 3709 | ... L53: =IFERROR('Data Sheet'!K62,0) -> 6878
B54: Capital Work in Progress | C54: =IFERROR('Data Sheet'!B63,0) -> 152.07 | D54: =IFERROR('Data Sheet'!C63,0) -> 43.37 | E54: =IFERROR('Data Sheet'!D63,0) -> 31.77 | F54: =IFERROR('Data Sheet'!E63,0) -> 18 | G54: =IFERROR('Data Sheet'!F63,0) -> 32 | H54: =IFERROR('Data Sheet'!G63,0) -> 85 | I54: =IFERROR('Data Sheet'!H63,0) -> 144 | J54: =IFERROR('Data Sheet'!I63,0) -> 97 | ... L54: =IFERROR('Data Sheet'!K63,0) -> 163
B55: Investments | C55: =IFERROR('Data Sheet'!B64,0) -> 430.73 | D55: =IFERROR('Data Sheet'!C64,0) -> 35.99 | E55: =IFERROR('Data Sheet'!D64,0) -> 108.42 | F55: =IFERROR('Data Sheet'!E64,0) -> 158 | G55: =IFERROR('Data Sheet'!F64,0) -> 2824 | H55: =IFERROR('Data Sheet'!G64,0) -> 294 | I55: =IFERROR('Data Sheet'!H64,0) -> 2515 | J55: =IFERROR('Data Sheet'!I64,0) -> 2345 | ... L55: =IFERROR('Data Sheet'!K64,0) -> 3506
B56: Other Assets | C56: =IFERROR('Data Sheet'!B65-SUM('Data Sheet'!B67:B69),0) -> 723.78 | D56: =IFERROR('Data Sheet'!C65-SUM('Data Sheet'!C67:C69),0) -> 1129.43 | E56: =IFERROR('Data Sheet'!D65-SUM('Data Sheet'!D67:D69),0) -> 1477.27 | F56: =IFERROR('Data Sheet'!E65-SUM('Data Sheet'!E67:E69),0) -> 1939 | G56: =IFERROR('Data Sheet'!F65-SUM('Data Sheet'!F67:F69),0) -> 1731 | H56: =IFERROR('Data Sheet'!G65-SUM('Data Sheet'!G67:G69),0) -> 2518 | I56: =IFERROR('Data Sheet'!H65-SUM('Data Sheet'!H67:H69),0) -> 2762 | J56: =IFERROR('Data Sheet'!I65-SUM('Data Sheet'!I67:I69),0) -> 3801 | ... L56: =IFERROR('Data Sheet'!K65-SUM('Data Sheet'!K67:K69),0) -> 4438
B57: Total Non Current Assets | C57: =SUM(C53:C56) -> 2495.3 | D57: =SUM(D53:D56) -> 2682.6 | E57: =SUM(E53:E56) -> 3184.09 | F57: =SUM(F53:F56) -> 4748 | G57: =SUM(G53:G56) -> 7110 | H57: =SUM(H53:H56) -> 5441 | I57: =SUM(I53:I56) -> 8419 | J57: =SUM(J53:J56) -> 9952 | ... L57: =SUM(L53:L56) -> 14985
...

Sheet Data>

Sheet Cash Flow Data
C2: 42064 | D2: 42430 | E2: 42795 | F2: 43160 | G2: 43525 | H2: 43891 | I2: 44256 | J2: 44621 | K2: 44986 | L2: 45352 | M2: 45717 | N2: 46082
B3: Cash from Operating Activity - | C3: 503 | D3: 576 | E3: 1712 | F3: -51 | G3: 1243 | H3: -348 | I3: 4139 | J3: -724 | K3: 1370 | L3: 1695 | M3: -541 | N3: 5590
B4: Profit from operations | C4: 1163 | D4: 942 | E4: 1073 | F4: 1642 | G4: 2183 | H4: 2481 | I4: 1789 | J4: 3298 | K4: 4937 | L4: 5404 | M4: 5774 | N4: 8447
B5: Receivables | C5: -39 | D5: 0 | E5: -12 | F5: -90 | G5: -139 | H5: 109 | I5: -59 | J5: -207 | K5: -112 | L5: -348 | M5: -95 | N5: 210
B6: Inventory | C6: -180 | D6: -398 | E6: -448 | F6: -996 | G6: -1120 | H6: -1057 | I6: -316 | J6: -5199 | K6: -2977 | L6: -2462 | M6: -9072 | N6: -11592
B7: Payables | C7: 1079 | D7: -245 | E7: 238 | F7: 95 | G7: 32 | H7: -310 | I7: 195 | J7: 504 | K7: -89 | L7: 196 | M7: 564 | N7: 472
B8: Loans Advances | C8: -71 | D8: -66 | E8: 0 | F8: 3 | G8: -24 | H8: -20 | I8: -8 | J8: -3 | K8: -18 | L8: -21 | M8: 4 | N8: -8
B9: Operating borrowings | C9: 0 | D9: 0 | E9: 763 | F9: -270 | G9: 741 | H9: -768 | I9: 2625 | J9: 1188 | K9: -99 | L9: 42 | M9: 2468 | N9: 7304
B10: Other WC items | C10: -1204 | D10: 545 | E10: 375 | F10: 22 | G10: 206 | H10: -226 | I10: 184 | J10: 497 | K10: 882 | L10: 57 | M10: 905 | N10: 2494
B11: Working capital changes | C11: -415 | D11: -163 | E11: 916 | F11: -1237 | G11: -304 | H11: -2272 | I11: 2621 | J11: -3220 | K11: -2413 | L11: -2536 | M11: -5226 | N11: -1120
B12: Direct taxes | C12: -245 | D12: -202 | E12: -277 | F12: -456 | G12: -636 | H12: -557 | I12: -271 | J12: -802 | K12: -1154 | L12: -1173 | M12: -1089 | N12: -1737
B13: Cash from Investing Activity - | C13: -118 | D13: -159 | E13: -953 | F13: 98 | G13: -797 | H13: 235 | I13: -2799 | J13: 1165 | K13: -1814 | L13: -189 | M13: 546 | N13: -2965
B14: Fixed assets purchased | C14: -209 | D14: -254 | E14: -256 | F14: -305 | G14: -265 | H14: -355 | I14: -146 | J14: -224 | K14: -432 | L14: -691 | M14: -494 | N14: -902
... B35: Net Cash Flow | C35: 2815 | D35: 5488 | E35: -2499 | F35: 4277 | G35: 4500 | H35: -2589 | I35: -3167 | J35: 730 | K35: 6843 | L35: -3092 | M35: 13232 | N35: 6459

Sheet Data Sheet
A1: COMPANY NAME | B1: TITAN COMPANY LTD | E1: =IF(B2<>B3, "A NEW VERSION OF THE WORKSHEET IS AVAILABLE", "")
A2: LATEST VERSION | B2: 2.1 | E2: PLEASE DO NOT MAKE ANY CHANGES TO THIS SHEET
A3: CURRENT VERSION | B3: 2.1
A5: META
A6: Number of shares | B6: =IF(B9>0, B9/B8, 0) -> 88.778617
A7: Face Value | B7: 1
A8: Current Price | B8: 4584.4
A9: Market Capitalization | B9: 406996.69
A15: PROFIT & LOSS | B15: =B26+B34 -> 1246.24 | K15: =K17-K18-K20-K21-K22-K23-K19 -> -9934
A16: Report Date | B16: 42825 | C16: 43190 | D16: 43555 | E16: 43921 | F16: 44286 | G16: 44651 | H16: 45016 | I16: 45382 | J16: 45747 | K16: 46112
A17: Sales | B17: 13260.83 | C17: 16119.77 | D17: 19778.52 | E17: 21052 | F17: 21644 | G17: 28799 | H17: 40575 | I17: 51084 | J17: 60456 | K17: 87584
A18: Raw Material Cost | B18: 9821.14 | C18: 12664.83 | D18: 15170.66 | E18: 16033 | F18: 16292 | G18: 26436 | H18: 32589 | I18: 42103 | J18: 55271 | K18: 80243
A19: Change in Inventory | B19: 313.71 | C19: 978.61 | D19: 776.41 | E19: 878 | F19: -122 | G19: 4795 | H19: 2234 | I19: 2671 | J19: 7815 | K19: 9936
A20: Power and Fuel | B20: 43.84 | C20: 45.32 | D20: 48.51 | E20: 52 | F20: 37 | G20: 45 | H20: 59 | I20: 71 | J20: 78 | K20: 87
A21: Other Mfr. Exp | B21: 160.42 | C21: 124.83 | D21: 193.28 | E21: 215 | F21: 141 | G21: 183 | H21: 225 | I21: 286 | J21: 326 | K21: 375
A22: Employee Cost | B22: 894.32 | C22: 906.26 | D22: 1024.44 | E22: 1204 | F22: 1069 | G22: 1356 | H22: 1656 | I22: 1875 | J22: 2164 | K22: 2692
A23: Selling and admin | B23: 1211.16 | C23: 1277.81 | D23: 1454.32 | E23: 1470 | F23: 1029 | G23: 1697 | H23: 2715 | I23: 3249 | J23: 3494 | K23: 4185
A24: Other Expenses | B24: 279.76 | C24: 435.13 | D24: 669.93 | E24: 493 | F24: 1229 | G24: 533 | H24: 683 | I24: 879 | J24: 1244 | K24: 1581
A25: Other Income | B25: -42.38 | C25: 69.93 | D25: 178.48 | E25: 153 | F25: 180 | G25: 177 | H25: 306 | I25: 534 | J25: 487 | K25: 450
A26: Depreciation | B26: 110.53 | C26: 131.43 | D26: 162.84 | E26: 348 | F26: 375 | G26: 399 | H26: 441 | I26: 584 | J26: 693 | K26: 826
A27: Interest | B27: 37.74 | C27: 52.92 | D27: 52.54 | E27: 166 | F27: 203 | G27: 218 | H27: 300 | I27: 619 | J27: 953 | K27: 1180
... A31: Dividend Amount | B31: 230.83 | C31: 332.92 | D31: 443.9 | E31: 356 | F31: 356 | G31: 667.5 | H31: 890 | I31: 979 | J31: 979 | K31: 1335
A32: Effective Tax Rate | B32: =B29/B28 -> 0.2835551 | C32: =C29/C28 -> 0.27969381 | D32: =D29/D28 -> 0.29037912 | E32: =E29/E28 -> 0.28972407 | F32: =F29/F28 -> 0.26601356 | G32: =G29/G28 -> 0.24311295 | H32: =H29/H28 -> 0.26377333 | I32: =I29/I28 -> 0.24378109 | ... K32: =K29/K28 -> 0.25408028
A34: EBITDA | B34: =+B30+B29+B27+B26 -> 1135.71 | C34: =+C30+C29+C27+C26 -> 1742.31 | D34: =+D30+D29+D27+D26 -> 2187.77 | E34: =+E30+E29+E27+E26 -> 2624 | F34: =+F30+F29+F27+F26 -> 1904 | G34: =+G30+G29+G27+G26 -> 3496 | H34: =+H30+H29+H27+H26 -> 5164 | I34: =+I30+I29+I27+I26 -> 5826 | ... K34: =+K30+K29+K27+K26 -> 8807
A40: Quarters
A41: Report Date | B41: 45291 | C41: 45382 | D41: 45473 | E41: 45565 | F41: 45657 | G41: 45747 | H41: 45838 | I41: 45930 | J41: 46022 | K41: 46112
A42: Sales | B42: 14164 | C42: 12494 | D42: 13266 | E42: 14534 | F42: 17740 | G42: 14916 | H42: 16523 | I42: 18725 | J42: 25416 | K42: 26920
A43: Expenses | B43: 12599 | C43: 11303 | D43: 12019 | E43: 13298 | F43: 16066 | G43: 13379 | H43: 14693 | I43: 16850 | J43: 22703 | K43: 24982
A44: Other Income | B44: 136 | C44: 159 | D44: 120 | E44: 123 | F44: 128 | G44: 116 | H44: 105 | I44: 113 | J44: -1 | K44: 235
A45: Depreciation | B45: 154 | C45: 158 | D45: 164 | E45: 171 | F45: 175 | G45: 183 | H45: 184 | I45: 189 | J45: 207 | K45: 246
A46: Interest | B46: 169 | C46: 201 | D46: 230 | E46: 240 | F46: 231 | G46: 252 | H46: 271 | I46: 277 | J46: 282 | K46: 350
A47: Profit before tax | B47: 1378 | C47: 991 | D47: 973 | E47: 948 | F47: 1396 | G47: 1218 | H47: 1480 | I47: 1522 | J47: 2223 | K47: 1577
A48: Tax | B48: 325 | C48: 220 | D48: 258 | E48: 244 | F48: 349 | G48: 347 | H48: 389 | I48: 402 | J48: 539 | K48: 398
A49: Net profit | B49: 1053 | C49: 771 | D49: 715 | E49: 704 | F49: 1047 | G49: 871 | H49: 1091 | I49: 1120 | J49: 1684 | K49: 1179
A50: Operating Profit | B50: 1565 | C50: 1191 | D50: 1247 | E50: 1236 | F50: 1674 | G50: 1537 | H50: 1830 | I50: 1875 | J50: 2713 | K50: 1938
A51: EBITDA | B51: =B49+B48+B46+B45 -> 1701 | C51: =C49+C48+C46+C45 -> 1350 | D51: =D49+D48+D46+D45 -> 1367 | E51: =E49+E48+E46+E45 -> 1359 | F51: =F49+F48+F46+F45 -> 1802 | G51: =G49+G48+G46+G45 -> 1653 | H51: =H49+H48+H46+H45 -> 1935 | I51: =I49+I48+I46+I45 -> 1988 | ... K51: =K49+K48+K46+K45 -> 2173
A55: BALANCE SHEET
A56: Report Date | B56: 42825 | C56: 43190 | D56: 43555 | E56: 43921 | F56: 44286 | G56: 44651 | H56: 45016 | I56: 45382 | J56: 45747 | K56: 46112
A57: Equity Share Capital | B57: 88.78 | C57: 88.78 | D57: 88.78 | E57: 89 | F57: 89 | G57: 89 | H57: 89 | I57: 89 | J57: 89 | K57: 89
A58: Reserves | B58: 4143.6 | C58: 5001.1 | D58: 5981.37 | E58: 6580 | F58: 7408 | G58: 9214 | H58: 11762 | I58: 9304 | J58: 11535 | K58: 15614
...

Sheet Modelling>

Sheet Beta Regression 
B1: Regression Beta - 3 Years Weekly
B3: Titan Weekly Returns | F3: Nifty Returns | I3: Drifted Beta
B5: Date | C5: Closing Price | D5: Return | F5: Closing Price | G5: Return | I5: Levered Raw Beta | J5: =M5 -> 1.0228208 | L5: Beta Reg1 | M5: =O31 -> 1.0228208
B6: 46149 | C6: 476.15 | D6: =C6/C7-1 -> 0.24630284 | F6: 24206.9 | G6: =F6/F7-1 -> -0.002634848 | I6: Raw Beta Weight | J6: 0.75 | L6: Beta Reg2 | M6: =SLOPE(D6:D108,G6:G108) -> 1.618719
B7: 06/28/2026 | C7: 382.05 | D7: =C7/C8-1 -> 0.011249338 | F7: 24270.85 | G7: =F7/F8-1 -> 0.0089312438
B8: 06/21/2026 | C8: 377.8 | D8: =C8/C9-1 -> -0.014863103 | F8: 24056 | G8: =F8/F9-1 -> 0.0017865249 | I8: Market Beta | J8: 1
B9: 06/14/2026 | C9: 383.5 | D9: =C9/C10-1 -> 0.11240029 | F9: 24013.1 | G9: =F9/F10-1 -> 0.01651787 | I9: Market Beta Weight | J9: 0.25
B10: 46209 | C10: 344.75 | D10: =C10/C11-1 -> -0.072878849 | F10: 23622.9 | G10: =F10/F11-1 -> 0.010964321
B11: 05/31/2026 | C11: 371.85 | D11: =C11/C12-1 -> 0.047317279 | F11: 23366.7 | G11: =F11/F12-1 -> -0.0076886327 | I11: Adjusted Beta | J11: =J5*J6+J8*J9 -> 1.0171156
B12: 05/24/2026 | C12: 355.05 | D12: =C12/C13-1 -> 0.0075198638 | F12: 23547.75 | G12: =F12/F13-1 -> -0.0072325069
B13: 05/17/2026 | C13: 352.4 | D13: =C13/C14-1 -> -0.001841099 | F13: 23719.3 | G13: =F13/F14-1 -> 0.0032059551
B14: 46300 | C14: 353.05 | D14: =C14/C15-1 -> -0.16841361 | F14: 23643.5 | G14: =F14/F15-1 -> -0.022032044 | N14: SUMMARY OUTPUT
B15: 46086 | C15: 424.55 | D15: =C15/C16-1 -> 0.028588734 | F15: 24176.15 | G15: =F15/F16-1 -> 0.0074424264
B16: 04/26/2026 | C16: 412.75 | D16: =C16/C17-1 -> 0.018381446 | F16: 23997.55 | G16: =F16/F17-1 -> 0.0041677215 | N16: Regression Statistics
B17: 04/19/2026 | C17: 405.3 | D17: =C17/C18-1 -> -0.050486119 | F17: 23897.95 | G17: =F17/F18-1 -> -0.018707745 | N17: Multiple R | O17: 0.57259707
B18: 46360 | C18: 426.85 | D18: =C18/C19-1 -> -0.049649338 | F18: 24353.55 | G18: =F18/F19-1 -> 0.012596359 | N18: R Square | O18: 0.32786741
B19: 46146 | C19: 449.15 | D19: =C19/C20-1 -> 0.13896285 | F19: 24050.6 | G19: =F19/F20-1 -> 0.058886722 | N19: Adjusted R Square | O19: 0.32114608
B20: 03/29/2026 | C20: 394.35 | D20: =C20/C21-1 -> 0.015449981 | F20: 22713.1 | G20: =F20/F21-1 -> -0.0046670406 | N20: Standard Error | O20: 0.026929189
B21: 03/22/2026 | C21: 388.35 | D21: =C21/C22-1 -> 0.014763522 | F21: 22819.6 | G21: =F21/F22-1 -> -0.012758225 | N21: Observations | O21: 102
B22: 03/15/2026 | C22: 382.7 | D22: =C22/C23-1 -> 0.009762533 | F22: 23114.5 | G22: =F22/F23-1 -> -0.0015809184
B23: 46237 | C23: 379 | D23: =C23/C24-1 -> -0.041840475 | F23: 23151.1 | G23: =F23/F24-1 -> -0.053142171 | N23: ANOVA
B24: 46025 | C24: 395.55 | D24: =C24/C25-1 -> -0.035479151 | F24: 24450.45 | G24: =F24/F25-1 -> -0.028921328 | O24: df | P24: SS | Q24: MS | R24: F | S24: Significance F
B25: 02/22/2026 | C25: 410.1 | D25: =C25/C26-1 -> 0.02218345 | F25: 25178.65 | G25: =F25/F26-1 -> -0.01535318 | N25: Regression | O25: 1 | P25: 0.035374462 | Q25: 0.035374462 | R25: 48.780168 | S25: 3.2167465e-10
B26: 02/15/2026 | C26: 401.2 | D26: =C26/C27-1 -> -0.040306183 | F26: 25571.25 | G26: =F26/F27-1 -> 0.0039319071 | N26: Residual | O26: 100 | P26: 0.072518123 | Q26: 0.00072518123
B27: 46236 | C27: 418.05 | D27: =C27/C28-1 -> 0.099408284 | F27: 25471.1 | G27: =F27/F28-1 -> -0.0086636024 | N27: Total | O27: 101 | P27: 0.10789259
B28: 46024 | C28: 380.25 | D28: =C28/C29-1 -> 0.051430942 | F28: 25693.7 | G28: =F28/F29-1 -> 0.014733034
B29: 01/25/2026 | C29: 361.65 | D29: =C29/C30-1 -> -0.015114379 | F29: 25320.65 | G29: =F29/F30-1 -> 0.010858869 | O29: Coefficients | P29: Standard Error | Q29: t Stat | R29: P-value | S29: Lower 95% | T29: Upper 95% | U29: Lower 95.0% | V29: Upper 95.0%
B30: 01/18/2026 | C30: 367.2 | D30: =C30/C31-1 -> -0.21454545 | F30: 25048.65 | G30: =F30/F31-1 -> -0.025130038 | N30: Intercept | O30: 0.0035484136 | P30: 0.0026664022 | Q30: 1.3307871 | R30: 0.18628554 | S30: -0.0017416525 | T30: 0.0088384797 | U30: -0.0017416525 | V30: 0.0088384797
B31: 46327 | C31: 467.5 | D31: =C31/C32-1 -> -0.077727362 | F31: 25694.35 | G31: =F31/F32-1 -> 0.00043024066 | N31: -0.002634848 | O31: 1.0228208 | P31: 0.14644614 | Q31: 6.9842801 | R31: 3.2167465e-10 | S31: 0.73227588 | T31: 1.3133658 | U31: 0.73227588 | V31: 1.3133658
B32: 46113 | C32: 506.9 | D32: =C32/C33-1 -> 0.022594311 | F32: 25683.3 | G32: =F32/F33-1 -> -0.024507616
B33: 12/28/2025 | C33: 495.7 | D33: =C33/C34-1 -> 0.0092639723 | F33: 26328.55 | G33: =F33/F34-1 -> 0.010991733
B34: 12/21/2025 | C34: 491.15 | D34: =C34/C35-1 -> 0.012993709 | F34: 26042.3 | G34: =F34/F35-1 -> 0.0029230082
B35: 12/14/2025 | C35: 484.85 | D35: =C35/C36-1 -> 0.011579387 | F35: 25966.4 | G35: =F35/F36-1 -> -0.0030924926
B36: 45850 | C36: 479.3 | D36: =C36/C37-1 -> -0.02680203 | F36: 26046.95 | G36: =F36/F37-1 -> -0.0053271826
B37: 11/30/2025 | C37: 492.5 | D37: =C37/C38-1 -> -0.025427921 | F37: 26186.45 | G37: =F37/F38-1 -> -0.00062970009
B38: 11/23/2025 | C38: 505.35 | D38: =C38/C39-1 -> 0.017927284 | F38: 26202.95 | G38: =F38/F39-1 -> 0.0051710612
B39: 11/16/2025 | C39: 496.45 | D39: =C39/C40-1 -> 0.0019172553 | F39: 26068.15 | G39: =F39/F40-1 -> 0.0061018794
B40: 45911 | C40: 495.5 | D40: =C40/C41-1 -> -0.033736349 | F40: 25910.05 | G40: =F40/F41-1 -> 0.016387301
B41: 45699 | C41: 512.8 | D41: =C41/C42-1 -> 0.006082009 | F41: 25492.3 | G41: =F41/F42-1 -> -0.0089339517
B42: 10/26/2025 | C42: 509.7 | D42: =C42/C43-1 -> 0.029073289 | F42: 25722.1 | G42: =F42/F43-1 -> -0.0028319277
...

Sheet Beta Comps and WACC 
B2: Using Top Down approach
B4: Peer Comps
G5: Debt/ | H5: Debt/ | I5: Levered | J5: Unlevered
B6: Name | C6: Country | D6: Total Debt | E6: Total Equity | F6: Tax Rate 1 | G6: Equity | H6: Capital | I6: Beta 2 | J6: Beta 3
B7: Titan Company | C7: India | D7: 30621 | E7: =D7/G7 -> 1570307.7 | F7: 0.25 | G7: 0.0195 | H7: =D7/(D7+E7) -> 0.019127023 | I7: 1.02 | J7: =I7/(1+(1-F7)*G7) -> 1.0052975
B8: Kalyan Jewellers | C8: India | D8: 6117.33 | E8: =D8/G8 -> 630652.58 | F8: 0.25 | G8: 0.0097 | H8: =D8/(D8+E8) -> 0.0096068139 | I8: 1.62 | J8: =I8/(1+(1-F8)*G8) -> 1.6082996
B9: Thangamayil Jew. | C9: India | D9: 913.21 | E9: =D9/G9 -> 142689.06 | F9: 0.25 | G9: 0.0064 | H9: =D9/(D9+E9) -> 0.0063593005 | I9: 0.9 | J9: =I9/(1+(1-F9)*G9) -> 0.89570064
B10: PC Jeweller | C10: India | D10: 1166.56 | E10: =D10/G10 -> 833257.14 | F10: 0.25 | G10: 0.0014 | H10: =D10/(D10+E10) -> 0.0013980427 | I10: 1.3 | J10: =I10/(1+(1-F10)*G10) -> 1.2986364
B11: Sky Gold & Diam. | C11: India | D11: 869.11 | E11: =D11/G11 -> 119056.16 | F11: 0.25 | G11: 0.0073 | H11: =D11/(D11+E11) -> 0.0072470962 | I11: 1.4 | J11: =I11/(1+(1-F11)*G11) -> 1.3923767
B12: Bluestone Jewel | C12: India | D12: 1699.09 | E12: =D12/G12 -> 180754.26 | F12: 0.25 | G12: 0.0094 | H12: =D12/(D12+E12) -> 0.0093124628 | I12: 0.7 | J12: =I12/(1+(1-F12)*G12) -> 0.69509955
B13: P N Gadgil Jewe. | C13: India | D13: 1737.09 | E13: =D13/G13 -> 195178.65 | F13: 0.25 | G13: 0.0089 | H13: =D13/(D13+E13) -> 0.0088214888 | I13: 0.9 | J13: =I13/(1+(1-F13)*G13) -> 0.89403233
H15: Average | I15: =AVERAGE(I7:I13) -> 1.12 | J15: =AVERAGE(J7:J13) -> 1.1127775
H16: Median | I16: =MEDIAN(I7:I13) -> 1.02 | J16: =MEDIAN(J7:J13) -> 1.0052975
B19: Cost of Equity | C19: =J19 + J20*J16 -> 0.13757083 | H19: Risk Free Rate | J19: 0.0672
H20: Equity Risk Premium | J20: 0.07
B21: Cost of Debt
B22: Pre tax Cost of Debt | C22: =J19+J22 -> 0.075 | H22: Default Spread of Titan Company | J22: 0.0078
B23: Tax Rate | C23: 0.25
B24: After tax Cost of Debt | C24: =C22*(1-C23) -> 0.05625
B26: WACC
B27: Debt Weight | C27: =D7/(D7+E7) -> 0.019127023
B28: Cost of Debt | C28: =C24 -> 0.05625
B29: Total Equity | C29: =E7/(D7+E7) -> 0.98087298
B30: Cost of Equity | C30: =C19 -> 0.13757083
B32: WACC | C32: =C27*C28+C29*C30 -> 0.1360154

Sheet Raw FS
C2: 42064 | D2: 42430 | E2: 42795 | F2: 43160 | G2: 43525 | H2: 43891 | I2: 44256 | J2: 44621 | K2: 44986 | L2: 45352 | M2: 45717 | N2: 46082
B3: Equity Capital | C3: 89 | D3: 89 | E3: 89 | F3: 89 | G3: 89 | H3: 89 | I3: 89 | J3: 89 | K3: 89 | L3: 89 | M3: 89 | N3: 89
B4: Reserves | C4: 2995 | D4: 3418 | E4: 4144 | F4: 5001 | G4: 5981 | H4: 6580 | I4: 7408 | J4: 9214 | K4: 11762 | L4: 9304 | M4: 11535 | N4: 15614
B6: Borrowings - | C6: 100 | D6: 113 | E6: 1882 | F6: 1691 | G6: 2393 | H6: 3562 | I6: 5638 | J6: 7275 | K6: 9367 | L6: 15528 | M6: 20777 | N6: 30621
B7: Long term Borrowings | C7: 0 | D7: 0 | E7: 0 | F7: 0 | G7: 32 | H7: 17 | I7: 9 | J7: 2 | K7: 0 | L7: 3302 | M7: 595 | N7: 93
B8: Short term Borrowings | C8: 100 | D8: 113 | E8: 1882 | F8: 1691 | G8: 2353 | H8: 2291 | I8: 4367 | J8: 5914 | K8: 7494 | L8: 9877 | M8: 17501 | N8: 27355
B9: Lease Liabilities | C9: 0 | D9: 0 | E9: 0 | F9: 0 | G9: 0 | H9: 1243 | I9: 1256 | J9: 1359 | K9: 1873 | L9: 2349 | M9: 2681 | N9: 3173
B10: Other Borrowings | C10: 0 | D10: 0 | E10: 0 | F10: 0 | G10: 8 | H10: 11 | I10: 6 | J10: 0 | K10: 0 | L10: 0 | M10: 0 | N10: 0
B11: Other Liabilities - | C11: 2684 | D11: 2723 | E11: 2293 | F11: 2740 | G11: 3247 | H11: 3313 | I11: 3309 | J11: 4610 | K11: 5802 | L11: 6626 | M11: 8244 | N11: 14237
B12: Non controlling int | C12: 0 | D12: 0 | E12: 26 | F12: -2 | G12: 14 | H12: 4 | I12: 5 | J12: 30 | K12: 53 | L12: 0 | M12: 0 | N12: 0
B13: Trade Payables | C13: 1940 | D13: 1655 | E13: 783 | F13: 878 | G13: 906 | H13: 596 | I13: 789 | J13: 1294 | K13: 1214 | L13: 1410 | M13: 1963 | N13: 2864
B14: Advance from Customers | C14: 160 | D14: 710 | E14: 943 | F14: 233 | G14: 290 | H14: 386 | I14: 479 | J14: 532 | K14: 718 | L14: 1085 | M14: 2140 | N14: 4745
B15: Other liability items | C15: 585 | D15: 358 | E15: 541 | F15: 1631 | G15: 2037 | H15: 2327 | I15: 2036 | J15: 2754 | K15: 3817 | L15: 4131 | M15: 4141 | N15: 6628
... B38: Total Assets | C38: 5868 | D38: 6342 | E38: 8408 | F38: 9521 | G38: 11710 | H38: 13544 | I38: 16444 | J38: 21188 | K38: 27020 | L38: 31547 | M38: 40645 | N38: 60561

Sheet Sales to Capital Ratio
B2: Calculation of ROIC | G2: 43891 | H2: 44256 | I2: 44621 | J2: 44986 | K2: 45352 | L2: 45717
B4: Current Assets
B5: Inventories | G5: ='Raw FS'!I33 -> 8408 | H5: ='Raw FS'!J33 -> 13609 | I5: ='Raw FS'!K33 -> 16584 | J5: ='Raw FS'!L33 -> 19051 | K5: ='Raw FS'!M33 -> 28184 | L5: ='Raw FS'!N33 -> 42743
B6: Trade receivables | G6: ='Raw FS'!I34 -> 366 | H6: ='Raw FS'!J34 -> 565 | I6: ='Raw FS'!K34 -> 674 | J6: ='Raw FS'!L34 -> 1018 | K6: ='Raw FS'!M34 -> 1068 | L6: ='Raw FS'!N34 -> 916
B7: Loans n Advances | G7: ='Raw FS'!I36 -> 109 | H7: ='Raw FS'!J36 -> 29 | I7: ='Raw FS'!K36 -> 167 | J7: ='Raw FS'!L36 -> 151 | K7: ='Raw FS'!M36 -> 324 | L7: ='Raw FS'!N36 -> 399
B8: Other asset items | G8: ='Raw FS'!I37 -> 1622 | H8: ='Raw FS'!J37 -> 2489 | I8: ='Raw FS'!K37 -> 2595 | J8: ='Raw FS'!L37 -> 3650 | K8: ='Raw FS'!M37 -> 3330 | L8: ='Raw FS'!N37 -> 4039
B9: Total Current Assets | G9: =SUM(G5:G8) -> 10505 | H9: =SUM(H5:H8) -> 16692 | I9: =SUM(I5:I8) -> 20020 | J9: =SUM(J5:J8) -> 23870 | K9: =SUM(K5:K8) -> 32906 | L9: =SUM(L5:L8) -> 48097
B11: Current Liabilities
B12: Trade Payables | G12: ='Raw FS'!I13 -> 789 | H12: ='Raw FS'!J13 -> 1294 | I12: ='Raw FS'!K13 -> 1214 | J12: ='Raw FS'!L13 -> 1410 | K12: ='Raw FS'!M13 -> 1963 | L12: ='Raw FS'!N13 -> 2864
B13: Advance from Customers | G13: ='Raw FS'!I14 -> 479 | H13: ='Raw FS'!J14 -> 532 | I13: ='Raw FS'!K14 -> 718 | J13: ='Raw FS'!L14 -> 1085 | K13: ='Raw FS'!M14 -> 2140 | L13: ='Raw FS'!N14 -> 4745
B14: Other liability items | G14: ='Raw FS'!I15 -> 2036 | H14: ='Raw FS'!J15 -> 2754 | I14: ='Raw FS'!K15 -> 3817 | J14: ='Raw FS'!L15 -> 4131 | K14: ='Raw FS'!M15 -> 4141 | L14: ='Raw FS'!N15 -> 6628
B15: Total Current Liabilities | G15: =SUM(G12:G14) -> 3304 | H15: =SUM(H12:H14) -> 4580 | I15: =SUM(I12:I14) -> 5749 | J15: =SUM(J12:J14) -> 6626 | K15: =SUM(K12:K14) -> 8244 | L15: =SUM(L12:L14) -> 14237
B17: Net Working Capital | G17: =G9-G15 -> 7201 | H17: =H9-H15 -> 12112 | I17: =I9-I15 -> 14271 | J17: =J9-J15 -> 17244 | K17: =K9-K15 -> 24662 | L17: =L9-L15 -> 33860
B19: Non Current Assets
B20: Land | G20: ='Raw FS'!I19 -> 108 | H20: ='Raw FS'!J19 -> 136 | I20: ='Raw FS'!K19 -> 144 | J20: ='Raw FS'!L19 -> 163 | K20: ='Raw FS'!M19 -> 163 | L20: ='Raw FS'!N19 -> 440
B21: Building | G21: ='Raw FS'!I20 -> 1617 | H21: ='Raw FS'!J20 -> 1853 | I21: ='Raw FS'!K20 -> 2403 | J21: ='Raw FS'!L20 -> 3546 | K21: ='Raw FS'!M20 -> 4177 | L21: ='Raw FS'!N20 -> 5239
B22: Plant Machinery | G22: ='Raw FS'!I21 -> 739 | H22: ='Raw FS'!J21 -> 768 | I22: ='Raw FS'!K21 -> 838 | J22: ='Raw FS'!L21 -> 899 | K22: ='Raw FS'!M21 -> 1012 | L22: ='Raw FS'!N21 -> 1197
B23: Equipments | G23: ='Raw FS'!I22 -> 76 | H23: ='Raw FS'!J22 -> 96 | I23: ='Raw FS'!K22 -> 130 | J23: ='Raw FS'!L22 -> 110 | K23: ='Raw FS'!M22 -> 127 | L23: ='Raw FS'!N22 -> 176
B24: Furniture n fittings | G24: ='Raw FS'!I23 -> 142 | H24: ='Raw FS'!J23 -> 159 | I24: ='Raw FS'!K23 -> 204 | J24: ='Raw FS'!L23 -> 212 | K24: ='Raw FS'!M23 -> 228 | L24: ='Raw FS'!N23 -> 264
B25: Railway sidings | G25: ='Raw FS'!I24 -> 309 | H25: ='Raw FS'!J24 -> 321 | I25: ='Raw FS'!K24 -> 376 | J25: ='Raw FS'!L24 -> 173 | K25: ='Raw FS'!M24 -> 193 | L25: ='Raw FS'!N24 -> 379
B26: Vehicles | G26: ='Raw FS'!I25 -> 30 | H26: ='Raw FS'!J25 -> 38 | I26: ='Raw FS'!K25 -> 40 | J26: ='Raw FS'!L25 -> 50 | K26: ='Raw FS'!M25 -> 57 | L26: ='Raw FS'!N25 -> 68
B27: Intangible Assets | G27: ='Raw FS'!I26 -> 320 | H27: ='Raw FS'!J26 -> 320 | I27: ='Raw FS'!K26 -> 320 | J27: ='Raw FS'!L26 -> 320 | K27: ='Raw FS'!M26 -> 320 | L27: ='Raw FS'!N26 -> 1782
B28: Other fixed assets | G28: ='Raw FS'!I27 -> 158 | H28: ='Raw FS'!J27 -> 157 | I28: ='Raw FS'!K27 -> 205 | J28: ='Raw FS'!L27 -> 305 | K28: ='Raw FS'!M27 -> 369 | L28: ='Raw FS'!N27 -> 540
B29: Gross Block | G29: =SUM(G20:G28) -> 3499 | H29: =SUM(H20:H28) -> 3848 | I29: =SUM(I20:I28) -> 4660 | J29: =SUM(J20:J28) -> 5778 | K29: =SUM(K20:K28) -> 6646 | L29: =SUM(L20:L28) -> 10085
B30: Accumulated Depriciation | G30: =-'Raw FS'!I29 -> -976 | H30: =-'Raw FS'!J29 -> -1304 | I30: =-'Raw FS'!K29 -> -1662 | J30: =-'Raw FS'!L29 -> -2069 | K30: =-'Raw FS'!M29 -> -2584 | L30: =-'Raw FS'!N29 -> -3207
B31: Net Fixed Income | G31: =SUM(G29:G30) -> 2523 | H31: =SUM(H29:H30) -> 2544 | I31: =SUM(I29:I30) -> 2998 | J31: =SUM(J29:J30) -> 3709 | K31: =SUM(K29:K30) -> 4062 | L31: =SUM(L29:L30) -> 6878
B33: Invested Capital | G33: =G31+G17 -> 9724 | H33: =H31+H17 -> 14656 | I33: =I31+I17 -> 17269 | J33: =J31+J17 -> 20953 | K33: =K31+K17 -> 28724 | L33: =L31+L17 -> 40738
B34: EBIT | G34: =HistoricalFS!G27 -> 1147 | H34: =HistoricalFS!H27 -> 2727 | I34: =HistoricalFS!I27 -> 4141 | J34: =HistoricalFS!J27 -> 4089 | K34: =HistoricalFS!K27 -> 4048 | L34: =HistoricalFS!L27 -> 6351
B36: ROIC | G36: =G34/G33 -> 0.11795557 | H36: =H34/H33 -> 0.18606714 | I36: =I34/I33 -> 0.23979385 | J36: =J34/J33 -> 0.19515105 | K36: =K34/K33 -> 0.14092745 | L36: =L34/L33 -> 0.15589867
K37: Average (5 yrs) | L37: =AVERAGE(H36:L36) -> 0.18356763
B39: Calculation of Sales to Capital Ratio | G39: 43891 | H39: 44256 | I39: 44621 | J39: 44986 | K39: 45352 | L39: 45717
B41: Invested Capital | G41: =G33 -> 9724 | H41: =H33 -> 14656 | I41: =I33 -> 17269 | J41: =J33 -> 20953 | K41: =K33 -> 28724 | L41: =L33 -> 40738
B42: Sales | G42: =HistoricalFS!G6 -> 21644 | H42: =HistoricalFS!H6 -> 28799 | I42: =HistoricalFS!I6 -> 40575 | J42: =HistoricalFS!J6 -> 51084 | K42: =HistoricalFS!K6 -> 60456 | L42: =HistoricalFS!L6 -> 87584
B44: Sales to Capital Ratio | G44: =G42/G41 -> 2.225833 | H44: =H42/H41 -> 1.9649973 | I44: =I42/I41 -> 2.349586 | J44: =J42/J41 -> 2.438028 | K44: =K42/K41 -> 2.1047208 | L44: =L42/L41 -> 2.1499337
K45: Average | L45: =AVERAGE(G44:L44) -> 2.2055165
B47: Calculation of Reinvestment Rate | G47: 43891 | H47: 44256 | I47: 44621 | J47: 44986 | K47: 45352 | L47: 45717
B49: Net Capex | G49: ='Cash Flow Data'!H14-'Cash Flow Data'!H15 -> -365 | H49: ='Cash Flow Data'!I14-'Cash Flow Data'!I15 -> -153 | I49: ='Cash Flow Data'!J14-'Cash Flow Data'!J15 -> -232 | J49: ='Cash Flow Data'!K14-'Cash Flow Data'!K15 -> -444 | K49: ='Cash Flow Data'!L14-'Cash Flow Data'!L15 -> -711 | L49: ='Cash Flow Data'!M14-'Cash Flow Data'!M15 -> -518
B50: Change in Working Capital | H50: =H17-G17 -> 4911 | I50: =I17-H17 -> 2159 | J50: =J17-I17 -> 2973 | K50: =K17-J17 -> 7418 | L50: =L17-K17 -> 9198
B52: EBIT | G52: =G34 -> 1147 | H52: =H34 -> 2727 | I52: =I34 -> 4141 | J52: =J34 -> 4089 | K52: =K34 -> 4048 | L52: =L34 -> 6351
B53: Tax Rate | G53: 0.25 | H53: 0.25 | I53: 0.25 | J53: 0.25 | K53: 0.25 | L53: 0.25
...

Sheet Int Growth Rate
B2: Years | C2: 44286 | D2: 44651 | E2: 45016 | F2: 45382 | G2: 45747 | H2: 46112 | I2: =H2+365 -> 46477 | J2: =I2+365 -> 46842 | K2: =J2+365 -> 47207 | L2: =K2+365 -> 47572 | M2: =L2+365 -> 47937 | N2: =M2+365 -> 48302 | O2: =N2+365 -> 48667 | P2: =O2+365 -> 49032 | ... R2: =Q2+365 -> 49762
B4: Sales | C4: =HistoricalFS!G6 -> 21644 | D4: =HistoricalFS!H6 -> 28799 | E4: =HistoricalFS!I6 -> 40575 | F4: =HistoricalFS!J6 -> 51084 | G4: =HistoricalFS!K6 -> 60456 | H4: =HistoricalFS!L6 -> 87584 | I4: =H4*(1+I5) -> 116148.07 | J4: =I4*(1+J5) -> 147208.65 | K4: =J4*(1+K5) -> 177074.02 | L4: =K4*(1+L5) -> 203635.12 | M4: =L4*(1+M5) -> 230616.78 | N4: =M4*(1+N5) -> 258146.65 | O4: =N4*(1+O5) -> 278798.39 | P4: =O4*(1+P5) -> 297384.95 | ... R4: =Q4*(1+R5) -> 325775.3
B5: Sales Growth | D5: =(D4-C4)/C4 -> 0.3305766 | E5: =(E4-D4)/D4 -> 0.40890309 | F5: =(F4-E4)/E4 -> 0.25900185 | G5: =(G4-F4)/F4 -> 0.18346253 | H5: =(H4-G4)/G4 -> 0.44872304 | I5: =H6 -> 0.32613342 | J5: =I5+(L5-$I$5)/3 -> 0.26742228 | K5: =J5+(M5-$I$5)/3 -> 0.20287781 | L5: =15% -> 0.15 | M5: =L5+($O$5-M5)/3 -> 0.1325 | N5: =M5+($O$5-N5)/3 -> 0.119375 | O5: 0.08 | P5: =O5+($R$5-$O$5)/3 -> 0.066666667 | Q5: =P5+($R$5-$O$5)/3 -> 0.053333333 | R5: 0.04
G6: Average | H6: =AVERAGE(D5:H5) -> 0.32613342
B7: Operating Income | C7: =HistoricalFS!G27 -> 1147 | D7: =HistoricalFS!H27 -> 2727 | E7: =HistoricalFS!I27 -> 4141 | F7: =HistoricalFS!J27 -> 4089 | G7: =HistoricalFS!K27 -> 4048 | H7: =HistoricalFS!L27 -> 6351 | I7: =I4*I8 -> 9083.9071 | J7: =J4*J8 -> 11833.918 | K7: =K4*K8 -> 14620.607 | L7: =L4*L8 -> 17257.425 | M7: =M4*M8 -> 20046.554 | N7: =N4*N8 -> 23002.12 | O7: =O4*O8 -> 25449.8 | P7: =P4*P8 -> 27794.463 | ... R7: =R4*R8 -> 32577.53
B8: % sales | C8: =C7/C4 -> 0.052993901 | D8: =D7/D4 -> 0.094690788 | E8: =E7/E4 -> 0.10205792 | F8: =F7/F4 -> 0.080044632 | G8: =G7/G4 -> 0.066957787 | H8: =H7/H4 -> 0.072513244 | I8: =H9 -> 0.078209712 | J8: =I8+($R$8-$I$8)/10 -> 0.080388741 | K8: =J8+($R$8-$I$8)/10 -> 0.082567769 | L8: =K8+($R$8-$I$8)/10 -> 0.084746798 | M8: =L8+($R$8-$I$8)/10 -> 0.086925827 | N8: =M8+($R$8-$I$8)/10 -> 0.089104856 | O8: =N8+($R$8-$I$8)/10 -> 0.091283885 | P8: =O8+($R$8-$I$8)/10 -> 0.093462914 | Q8: =P8+($R$8-$I$8)/10 -> 0.095641942 | R8: 0.1
G9: Average | H9: =AVERAGE(C8:H8) -> 0.078209712
B10: Increase in Revenue | D10: =D4-C4 -> 7155 | E10: =E4-D4 -> 11776 | F10: =F4-E4 -> 10509 | G10: =G4-F4 -> 9372 | H10: =H4-G4 -> 27128 | I10: =I4-H4 -> 28564.07 | J10: =J4-I4 -> 31060.582 | K10: =K4-J4 -> 29865.368 | ... R10: =R4-Q4 -> 12529.819
B11: Reinvestment | D11: =D10/'Sales to Capital Ratio'!$L$45 -> 3244.1381 | E11: =E10/'Sales to Capital Ratio'!$L$45 -> 5339.339 | F11: =F10/'Sales to Capital Ratio'!$L$45 -> 4764.8704 | G11: =G10/'Sales to Capital Ratio'!$L$45 -> 4249.3449 | H11: =H10/'Sales to Capital Ratio'!$L$45 -> 12300.067 | I11: =I10/'Sales to Capital Ratio'!$L$45 -> 12951.193 | J11: =J10/'Sales to Capital Ratio'!$L$45 -> 14083.133 | K11: =K10/'Sales to Capital Ratio'!$L$45 -> 13541.213 | ... R11: =R10/'Sales to Capital Ratio'!$L$45 -> 5681.127
B20: RoiC not stable, can't use directly the ROC*Reinvestment rate
B22: Because of it's heavy market share, we will admit that it will grow with higher rates for first 5 years and then they will nmove towards stabilization
B23: We would distribute the time period as 3 stages, first the continuing growth phase, second is moderating and the third is going towards stability
B24: For stable margin they need to reach the industry average in each of the business and that would be aroundb 10% at the end

Sheet DCF
B2: Calculation of PV of FCFF | E2: 46082 | F2: =E2+366 -> 46448 | G2: =F2+366 -> 46814 | H2: =G2+366 -> 47180 | I2: =H2+366 -> 47546 | J2: =I2+366 -> 47912 | K2: =J2+366 -> 48278 | L2: =K2+366 -> 48644 | M2: =L2+366 -> 49010 | ... O2: =N2+366 -> 49742
B4: EBIT (Operational Income ) | E4: ='Int Growth Rate'!H7 -> 6351 | F4: ='Int Growth Rate'!I7 -> 9083.9071 | G4: ='Int Growth Rate'!J7 -> 11833.918 | H4: ='Int Growth Rate'!K7 -> 14620.607 | I4: ='Int Growth Rate'!L7 -> 17257.425 | J4: ='Int Growth Rate'!M7 -> 20046.554 | K4: ='Int Growth Rate'!N7 -> 23002.12 | L4: ='Int Growth Rate'!O7 -> 25449.8 | ... O4: ='Int Growth Rate'!R7 -> 32577.53
B5: Tax Rate | E5: 0.25 | F5: 0.25 | G5: 0.25 | H5: 0.25 | I5: 0.25 | J5: 0.25 | K5: 0.25 | L5: 0.25 | M5: 0.25 | N5: 0.25 | O5: 0.25
B6: EBIT(1-T) | E6: =E4*(1-E5) -> 4763.25 | F6: =F4*(1-F5) -> 6812.9303 | G6: =G4*(1-G5) -> 8875.4386 | H6: =H4*(1-H5) -> 10965.455 | I6: =I4*(1-I5) -> 12943.068 | J6: =J4*(1-J5) -> 15034.916 | K6: =K4*(1-K5) -> 17251.59 | L6: =L4*(1-L5) -> 19087.35 | ... O6: =O4*(1-O5) -> 24433.147
B7: Less: Reinvestment | E7: ='Int Growth Rate'!H11 -> 12300.067 | F7: ='Int Growth Rate'!I11 -> 12951.193 | G7: ='Int Growth Rate'!J11 -> 14083.133 | H7: ='Int Growth Rate'!K11 -> 13541.213 | I7: ='Int Growth Rate'!L11 -> 12043.031 | J7: ='Int Growth Rate'!M11 -> 12233.712 | K7: ='Int Growth Rate'!N11 -> 12482.282 | L7: ='Int Growth Rate'!O11 -> 9363.6719 | ... O7: ='Int Growth Rate'!R11 -> 5681.127
B8: Free Cash Flow to Firm | E8: =E6-E7 -> -7536.8169 | F8: =F6-F7 -> -6138.2629 | G8: =G6-G7 -> -5207.6945 | H8: =H6-H7 -> -2575.758 | I8: =I6-I7 -> 900.03751 | J8: =J6-J7 -> 2801.2032 | K8: =K6-K7 -> 4769.3086 | L8: =L6-L7 -> 9723.678 | ... O8: =O6-O7 -> 18752.02
B9: Mid Year Convention | F9: 0.5 | G9: =F9+1 -> 1.5 | H9: =G9+1 -> 2.5 | I9: =H9+1 -> 3.5 | J9: =I9+1 -> 4.5 | K9: =J9+1 -> 5.5 | L9: =K9+1 -> 6.5 | M9: =L9+1 -> 7.5 | N9: =M9+1 -> 8.5 | O9: =N9+1 -> 9.5
B10: Discounting Factor | F10: =1/(1+$D$15)^F9 -> 0.93822692 | G10: =1/(1+$D$15)^G9 -> 0.82589278 | H10: =1/(1+$D$15)^H9 -> 0.72700844 | I10: =1/(1+$D$15)^I9 -> 0.63996354 | J10: =1/(1+$D$15)^J9 -> 0.56334055 | K10: =1/(1+$D$15)^K9 -> 0.49589165 | L10: =1/(1+$D$15)^L9 -> 0.43651842 | M10: =1/(1+$D$15)^M9 -> 0.38425396 | ... O10: =1/(1+$D$15)^O9 -> 0.29774873
B12: PV of FCFF | F12: =F8*F10 -> -5759.0835 | G12: =G8*G10 -> -4300.9973 | H12: =H8*H10 -> -1872.5978 | I12: =I8*I10 -> 575.99119 | J12: =J8*J10 -> 1578.0314 | K12: =K8*K10 -> 2365.0603 | L12: =L8*L10 -> 4244.5645 | M12: =M8*M10 -> 4771.8743 | ... O12: =O8*O10 -> 5583.3902
B14: Terminal Growth | D14: 0.04
B15: WACC | D15: ='Beta Comps and WACC '!C32 -> 0.1360154
B17: Calculation of Terminal Value | F17: Sensitivity Analysis
F18: =D37 -> 62.205357 | G18: 0.06 | H18: 0.08 | I18: 0.0994 | J18: 0.12
B19: FCFF(n+1) | D19: =O12*(1+0.08) -> 6030.0614 | F19: 0.02 | G19: 505.54868 | H19: 361.43135 | I19: 291.00626 | J19: 246.13749
B20: WACC | D20: =D15 -> 0.1360154 | F20: =F19+0.01 -> 0.03 | G20: 649.66602 | H20: 419.07829 | I20: 322.39092 | J20: 265.35313
B21: Terminal Growth Rate | D21: =D14 -> 0.04 | F21: =F20+0.01 -> 0.04 | G21: 937.90068 | H21: 505.54868 | I21: 364.34281 | J21: 289.37269
F22: =F21+0.01 -> 0.05 | G22: 1802.6047 | H22: 649.66602 | I22: 423.27928 | J22: 320.25497
B23: Terminal Value of FCFF | D23: =D19/(D20-D21) -> 62803.064
B25: Calculation of Equity Value per Share
B27: PV of FCFF | D27: =SUM(F12:O12) -> 12354.059
B28: PV of Terminal Value | D28: =D23*O10 -> 18699.532
B29: Value of Operating Assets (Enterprise Value ) | D29: =SUM(D27:D28) -> 31053.592
B31: Add: Cash | D31: ='Data Sheet'!K69 -> 1917
B32: Less: Debt | D32: ='Raw FS'!N7+'Raw FS'!N8 -> 27448
B34: Equity Value | D34: =D29+D31-D32 -> 5522.5916
B35: No of Shares | D35: 88.78
B37: Equity Value per Share | D37: =D34/D35 -> 62.205357
B39: Share Price | D39: 4590
B40: Discounted/Premium | D40: =D39/D37 -> 73.787857
D41: Premium

Sheet Relative Valuation 
C2: Market Data | J2: Financials | N2: Valuation
C3: Share | D3: Share | E3: Equity | H3: Enterprise
B4: Company | C4: Price | D4: Outstanding | E4: Value | F4: Net Debt | G4: Cash | H4: Value | J4: Revenue | K4: EBITDA | L4: Net Income | N4: EV/Revenue | O4: EV/EBITDA | P4: P/E
B5: Titan Company | C5: 4711.6 | D5: 88.78 | E5: 418347.33
B6: Kalyan Jewellers | C6: 596.1 | D6: 103.27 | E6: 61566.98
B7: Thangamayil Jew. | C7: 6476 | D7: 3.11 | E7: 20137.92
B8: Bluestone Jewel | C8: 776.05 | D8: 15.24 | E8: 11851.1
B9: Sky Gold & Diam. | C9: 671.25 | D9: 15.49 | E9: 10391.16
B10: PC Jeweller | C10: 9.87 | D10: 971.05 | E10: 9603.35
B11: P N Gadgil Jewe. | C11: 636.6 | D11: 13.57 | E11: 8634.88
B21: S.No. | C21: Name | D21: CMP Rs. | E21: Debt / Eq | F21: BV of Equity | H21: Market D/E | I21: Mar Cap Rs.Cr. | J21: B.V. Rs. | K21: Debt Rs.Cr. | L21: EPS 12M Rs. | M21: P/E | N21: EV / EBITDA | O21: EV Rs.Cr. | P21: No. Eq. Shares Cr.
B22: 1 | E22: 1.95 | F22: =K22/E22 -> 15703.077 | H22: =E22*(F22/I22) -> 0.073195161 | I22: 418347.33 | J22: 176.88 | K22: 30621 | L22: 57.14 | M22: 81.24 | N22: 50.17 | O22: 447051.33 | P22: 88.78
B23: 2 | E23: 0.97 | F23: =K23/E23 -> 6306.5258 | H23: =E23*(F23/I23) -> 0.099360566 | I23: 61566.98 | J23: 61.09 | K23: 6117.33 | L23: 13.08 | M23: 44.67 | N23: 24.76 | O23: 66823.4 | P23: 103.27
B24: 3 | E24: 0.64 | F24: =K24/E24 -> 1426.8906 | H24: =E24*(F24/I24) -> 0.045347782 | I24: 20137.92 | J24: 455.57 | K24: 913.21 | L24: 113.14 | M24: 56.98 | N24: 35.69 | O24: 20669.9 | P24: 3.11
B25: 4 | E25: 0.94 | F25: =K25/E25 -> 1807.5426 | H25: =E25*(F25/I25) -> 0.14336981 | I25: 11851.1 | J25: 118.29 | K25: 1699.09 | L25: 3.71 | M25: 210.42 | N25: 26.69 | O25: 13038.52 | P25: 15.24
B26: 5 | E26: 0.73 | F26: =K26/E26 -> 1190.5616 | H26: =E26*(F26/I26) -> 0.083639363 | I26: 10391.16 | J26: 77.39 | K26: 869.11 | L26: 17.78 | M26: 37.74 | N26: 23.42 | O26: 11024.83 | P26: 15.49
B27: 6 | E27: 0.14 | F27: =K27/E27 -> 8332.5714 | H27: =E27*(F27/I27) -> 0.12147428 | I27: 9603.35 | J27: 9.45 | K27: 1166.56 | L27: 0.83 | M27: 13.43 | N27: 12.25 | O27: 10633.74 | P27: 971.05
B28: 7 | E28: 0.89 | F28: =K28/E28 -> 1951.7865 | H28: =E28*(F28/I28) -> 0.2011713 | I28: 8634.88 | J28: 144.63 | K28: 1737.09 | L28: 30.2 | M28: 20.94 | N28: 14.02 | O28: 9867.52 | P28: 13.57
